# from src.utils.common import DataUtils
# from src.exceptions.CustomException import CustomException

# utilities = DataUtils()
# try:
#     X,y = utilities.load_data_uciml(repo_id=529)

# except ValueError as e:
#     err = CustomException(error_message=e).log_exception()
# except Exception as e:
#     err = CustomException(error_message=e).log_exception()
# else:
#     print(X)